<?xml version='1.0' encoding='utf-8'?>
<robot name="2198_scaled.urdf">
  <material name="body_color">
    <color rgba="0.2 0.05 0.8 0.3" />
    <texture />
    </material>
  <material name="body_color_R">
    <color rgba="0.8 0.05 0.2 0.6" />
    <texture />
    </material>
  <material name="body_color_L">
    <color rgba="0.05 0.8 0.2 0.6" />
    <texture />
    </material>
  <material name="Black">
    <color rgba="0 0 0 1" />
    <texture />
    </material>
  <material name="marker_color">
    <color rgba="1 0 0 1" />
    <texture />
    </material>
  <link name="middle_pelvis">
    <inertial>
      <mass value="10.65" />
      <origin xyz="0.030000 -0.025000 -0.001000" rpy="0 0 0" />
      <inertia ixx="0.08977" ixy="-0.0055" ixz="-0.00127" iyy="0.09888" iyz="-0.00056" izz="0.07942" />
      </inertial>
    <visual>
      <origin xyz="0.000000 -0.050000 0.000000" rpy="0.000000 -0.000000 0.000000" />
      <geometry>
        <mesh filename="meshes/pelvis_mesh.STL" scale="0.006300 0.005800 0.005800" />
        </geometry>
      <material name="body_color" />
      </visual>
    </link>
  <link name="left_upperleg_virtual">
    <inertial>
      <mass value="0.0" />
      <origin xyz="0.000000 0.000000 0.000000" rpy="0 0 0" />
      <inertia ixx="0.0" ixy="0.0" ixz="0.0" iyy="0.0" iyz="0.0" izz="0.0" />
      </inertial>
    </link>
  <link name="left_upperleg_virtual_2">
    <inertial>
      <mass value="0.0" />
      <origin xyz="0.000000 0.000000 0.000000" rpy="0 0 0" />
      <inertia ixx="0.0" ixy="0.0" ixz="0.0" iyy="0.0" iyz="0.0" izz="0.0" />
      </inertial>
    </link>
  <link name="left_upperleg">
    <inertial>
      <mass value="9.22" />
      <origin xyz="-0.018000 -0.188000 0.014000" rpy="0 0 0" />
      <inertia ixx="0.1497" ixy="0.00872" ixz="-0.00071" iyy="0.04005" iyz="-0.00872" izz="0.1602" />
      </inertial>
    <visual>
      <origin xyz="0.000000 -0.050000 0.000000" rpy="0.000000 -0.000000 0.000000" />
      <geometry>
        <mesh filename="meshes/upperleg_mesh.STL" scale="0.006200 0.006400 0.006900" />
        </geometry>
      <material name="body_color_L" />
      </visual>
    </link>
  <link name="left_lowerleg">
    <inertial>
      <mass value="3.6" />
      <origin xyz="-0.021000 -0.181000 0.003000" rpy="0 0 0" />
      <inertia ixx="0.05471" ixy="0.00112" ixz="0.00028" iyy="0.00698" iyz="0.00174" izz="0.05471" />
      </inertial>
    <visual>
      <origin xyz="0.000000 0.000000 0.000000" rpy="0.000000 -0.000000 0.000000" />
      <geometry>
        <mesh filename="meshes/lowerleg_mesh.STL" scale="0.006300 0.006600 0.007000" />
        </geometry>
      <material name="body_color_L" />
      </visual>
    <visual>
      <origin xyz="0.000000 0.000000 0.000000" rpy="0.000000 -0.000000 0.000000" />
      <geometry>
        <mesh filename="meshes/knee_mesh.STL" scale="0.005600 0.005600 0.005600" />
        </geometry>
      <material name="body_color_L" />
      </visual>
    </link>
  <link name="left_foot_virtual">
    <inertial>
      <mass value="0.0" />
      <origin xyz="0.000000 0.000000 0.000000" rpy="0 0 0" />
      <inertia ixx="0.0" ixy="0.0" ixz="0.0" iyy="0.0" iyz="0.0" izz="0.0" />
      </inertial>
    </link>
  <link name="left_foot">
    <inertial>
      <mass value="0.9" />
      <origin xyz="0.068000 -0.027000 0.005000" rpy="0 0 0" />
      <inertia ixx="0.00081" ixy="0.00048" ixz="-0.00018" iyy="0.00385" iyz="0.0" izz="0.00364" />
      </inertial>
    <visual>
      <origin xyz="0.000000 0.000000 0.000000" rpy="0.000000 -0.000000 0.000000" />
      <geometry>
        <mesh filename="meshes/foot_mesh.STL" scale="0.006700 0.006700 0.006700" />
        </geometry>
      <material name="body_color_L" />
      </visual>
    </link>
  <link name="middle_abdomen_virtual">
    <inertial>
      <mass value="0.0" />
      <origin xyz="0.000000 0.000000 0.000000" rpy="0 0 0" />
      <inertia ixx="0.0" ixy="0.0" ixz="0.0" iyy="0.0" iyz="0.0" izz="0.0" />
      </inertial>
    </link>
  <link name="middle_abdomen">
    <inertial>
      <mass value="12.25" />
      <origin xyz="-0.008000 0.100000 0.000000" rpy="0 0 0" />
      <inertia ixx="0.04427" ixy="0.01968" ixz="-0.00024" iyy="0.03796" iyz="-0.00097" izz="0.04761" />
      </inertial>
    <visual>
      <origin xyz="0.000000 0.000000 0.000000" rpy="0.000000 -0.000000 0.000000" />
      <geometry>
        <mesh filename="meshes/abdomen_mesh.STL" scale="0.007400 0.007400 0.007400" />
        </geometry>
      <material name="body_color" />
      </visual>
    </link>
  <link name="middle_thorax_virtual">
    <inertial>
      <mass value="0.0" />
      <origin xyz="0.000000 0.000000 0.000000" rpy="0 0 0" />
      <inertia ixx="0.0" ixy="0.0" ixz="0.0" iyy="0.0" iyz="0.0" izz="0.0" />
      </inertial>
    </link>
  <link name="middle_thorax_virtual_2">
    <inertial>
      <mass value="0.0" />
      <origin xyz="0.000000 0.000000 0.000000" rpy="0 0 0" />
      <inertia ixx="0.0" ixy="0.0" ixz="0.0" iyy="0.0" iyz="0.0" izz="0.0" />
      </inertial>
    </link>
  <link name="middle_thorax">
    <inertial>
      <mass value="11.97" />
      <origin xyz="-0.009000 0.127000 -0.001000" rpy="0 0 0" />
      <inertia ixx="0.05463" ixy="0.02428" ixz="-0.0003" iyy="0.04683" iyz="-0.0012" izz="0.05875" />
      </inertial>
    <visual>
      <origin xyz="0.000000 -0.188511 0.000000" rpy="0.000000 -0.000000 0.000000" />
      <geometry>
        <mesh filename="meshes/torso_mesh.STL" scale="0.007000 0.007000 0.007000" />
        </geometry>
      <material name="body_color" />
      </visual>
    </link>
  <link name="left_clavicle">
    <inertial>
      <mass value="0.156" />
      <origin xyz="-0.011096 0.006370 0.054170" rpy="0 0 0" />
      <inertia ixx="0.00024000000000000003" ixy="-2e-05" ixz="-7e-05" iyy="0.00026" iyz="5e-05" izz="4e-05" />
      </inertial>
    </link>
  <link name="left_upperarm_virtual">
    <inertial>
      <mass value="0.0" />
      <origin xyz="0.000000 0.000000 0.000000" rpy="0 0 0" />
      <inertia ixx="0.0" ixy="0.0" ixz="0.0" iyy="0.0" iyz="0.0" izz="0.0" />
      </inertial>
    </link>
  <link name="left_upperarm_virtual_2">
    <inertial>
      <mass value="0.0" />
      <origin xyz="0.000000 0.000000 0.000000" rpy="0 0 0" />
      <inertia ixx="0.0" ixy="0.0" ixz="0.0" iyy="0.0" iyz="0.0" izz="0.0" />
      </inertial>
    </link>
  <link name="left_upperarm">
    <inertial>
      <mass value="1.8" />
      <origin xyz="0.005000 -0.125000 -0.007000" rpy="0 0 0" />
      <inertia ixx="0.01314" ixy="0.00049" ixz="0.00034" iyy="0.00268" iyz="5e-05" izz="0.014" />
      </inertial>
    <visual>
      <origin xyz="0.000000 0.000000 0.000000" rpy="0.000000 -0.000000 0.000000" />
      <geometry>
        <mesh filename="meshes/shoulder_mesh.STL" scale="0.003900 0.003900 0.003900" />
        </geometry>
      <material name="body_color_L" />
      </visual>
    <visual>
      <origin xyz="0.000000 0.050000 0.000000" rpy="0.000000 -0.000000 0.000000" />
      <geometry>
        <mesh filename="meshes/upperarm_mesh.STL" scale="0.006300 0.006000 0.006900" />
        </geometry>
      <material name="body_color_L" />
      </visual>
    </link>
  <link name="left_lowerarm_virtual">
    <inertial>
      <mass value="0.0" />
      <origin xyz="0.000000 0.000000 0.000000" rpy="0 0 0" />
      <inertia ixx="0.0" ixy="0.0" ixz="0.0" iyy="0.0" iyz="0.0" izz="0.0" />
      </inertial>
    </link>
  <link name="left_lowerarm">
    <inertial>
      <mass value="1.28" />
      <origin xyz="0.003000 -0.120000 0.004000" rpy="0 0 0" />
      <inertia ixx="0.00825" ixy="9e-05" ixz="4e-05" iyy="0.0012700000000000003" iyz="-0.00067" izz="0.00767" />
      </inertial>
    <visual>
      <origin xyz="0.000000 0.000000 0.000000" rpy="0.000000 -0.000000 0.000000" />
      <geometry>
        <mesh filename="meshes/lowerarm_mesh.STL" scale="0.006400 0.006400 0.006400" />
        </geometry>
      <material name="body_color_L" />
      </visual>
    <visual>
      <origin xyz="0.000000 0.000000 0.000000" rpy="0.000000 -0.000000 0.000000" />
      <geometry>
        <mesh filename="meshes/elbow_mesh.STL" scale="0.005500 0.005500 0.005500" />
        </geometry>
      <material name="body_color_L" />
      </visual>
    </link>
  <link name="left_hand_virtual">
    <inertial>
      <mass value="0.0" />
      <origin xyz="0.000000 0.000000 0.000000" rpy="0 0 0" />
      <inertia ixx="0.0" ixy="0.0" ixz="0.0" iyy="0.0" iyz="0.0" izz="0.0" />
      </inertial>
    </link>
  <link name="left_hand">
    <inertial>
      <mass value="0.45" />
      <origin xyz="0.015000 -0.153000 0.014000" rpy="0 0 0" />
      <inertia ixx="0.00558" ixy="0.00073" ixz="0.00034" iyy="0.00216" iyz="-0.0006" izz="0.0047" />
      </inertial>
    <visual>
      <origin xyz="0.000000 0.000000 0.000000" rpy="0.000000 -0.000000 0.000000" />
      <geometry>
        <mesh filename="meshes/hand_mesh.STL" scale="0.006100 0.006100 0.006100" />
        </geometry>
      <material name="body_color_L" />
      </visual>
    </link>
  <link name="middle_head_virtual">
    <inertial>
      <mass value="0.0" />
      <origin xyz="0.000000 0.000000 0.000000" rpy="0 0 0" />
      <inertia ixx="0.0" ixy="0.0" ixz="0.0" iyy="0.0" iyz="0.0" izz="0.0" />
      </inertial>
    </link>
  <link name="middle_head_virtual_2">
    <inertial>
      <mass value="0.0" />
      <origin xyz="0.000000 0.000000 0.000000" rpy="0 0 0" />
      <inertia ixx="0.0" ixy="0.0" ixz="0.0" iyy="0.0" iyz="0.0" izz="0.0" />
      </inertial>
    </link>
  <link name="middle_head">
    <inertial>
      <mass value="5.03" />
      <origin xyz="-0.015000 0.131000 0.000000" rpy="0 0 0" />
      <inertia ixx="0.02688" ixy="-0.00227" ixz="-0.00011" iyy="0.01748" iyz="0.00025" izz="0.03046" />
      </inertial>
    <visual>
      <origin xyz="0.000000 0.000000 0.000000" rpy="0.000000 -0.000000 0.000000" />
      <geometry>
        <mesh filename="meshes/head_mesh.STL" scale="0.005600 0.005600 0.005600" />
        </geometry>
      <material name="body_color" />
      </visual>
    <visual>
      <origin xyz="0.000000 0.000000 0.000000" rpy="0.000000 -0.000000 0.000000" />
      <geometry>
        <mesh filename="meshes/neck_mesh.STL" scale="0.005000 0.005000 0.005000" />
        </geometry>
      <material name="body_color" />
      </visual>
    </link>
  <link name="right_clavicle">
    <inertial>
      <mass value="0.156" />
      <origin xyz="-0.011096 0.006370 0.054170" rpy="0 0 0" />
      <inertia ixx="0.00024000000000000003" ixy="-2e-05" ixz="-7e-05" iyy="0.00026" iyz="5e-05" izz="4e-05" />
      </inertial>
    </link>
  <link name="right_upperarm_virtual">
    <inertial>
      <mass value="0.0" />
      <origin xyz="0.000000 0.000000 0.000000" rpy="0 0 0" />
      <inertia ixx="0.0" ixy="0.0" ixz="0.0" iyy="0.0" iyz="0.0" izz="0.0" />
      </inertial>
    </link>
  <link name="right_upperarm_virtual_2">
    <inertial>
      <mass value="0.0" />
      <origin xyz="0.000000 0.000000 0.000000" rpy="0 0 0" />
      <inertia ixx="0.0" ixy="0.0" ixz="0.0" iyy="0.0" iyz="0.0" izz="0.0" />
      </inertial>
    </link>
  <link name="right_upperarm">
    <inertial>
      <mass value="1.8" />
      <origin xyz="0.005000 -0.125000 -0.007000" rpy="0 0 0" />
      <inertia ixx="0.01314" ixy="0.00049" ixz="0.00034" iyy="0.00268" iyz="5e-05" izz="0.014" />
      </inertial>
    <visual>
      <origin xyz="0.000000 0.000000 0.000000" rpy="0.000000 -0.000000 0.000000" />
      <geometry>
        <mesh filename="meshes/shoulder_mesh.STL" scale="0.003900 0.003900 0.003900" />
        </geometry>
      <material name="body_color_R" />
      </visual>
    <visual>
      <origin xyz="0.000000 0.050000 0.000000" rpy="0.000000 -0.000000 0.000000" />
      <geometry>
        <mesh filename="meshes/upperarm_mesh.STL" scale="0.006300 0.006000 0.006900" />
        </geometry>
      <material name="body_color_R" />
      </visual>
    </link>
  <link name="right_lowerarm_virtual">
    <inertial>
      <mass value="0.0" />
      <origin xyz="0.000000 0.000000 0.000000" rpy="0 0 0" />
      <inertia ixx="0.0" ixy="0.0" ixz="0.0" iyy="0.0" iyz="0.0" izz="0.0" />
      </inertial>
    </link>
  <link name="right_lowerarm">
    <inertial>
      <mass value="1.28" />
      <origin xyz="0.003000 -0.120000 0.004000" rpy="0 0 0" />
      <inertia ixx="0.00825" ixy="9e-05" ixz="4e-05" iyy="0.0012700000000000003" iyz="-0.00067" izz="0.00767" />
      </inertial>
    <visual>
      <origin xyz="0.000000 0.000000 0.000000" rpy="0.000000 -0.000000 0.000000" />
      <geometry>
        <mesh filename="meshes/lowerarm_mesh.STL" scale="0.006400 0.006400 0.006400" />
        </geometry>
      <material name="body_color_R" />
      </visual>
    <visual>
      <origin xyz="0.000000 0.000000 0.000000" rpy="0.000000 -0.000000 0.000000" />
      <geometry>
        <mesh filename="meshes/elbow_mesh.STL" scale="0.005500 0.005500 0.005500" />
        </geometry>
      <material name="body_color_R" />
      </visual>
    </link>
  <link name="right_hand_virtual">
    <inertial>
      <mass value="0.0" />
      <origin xyz="0.000000 0.000000 0.000000" rpy="0 0 0" />
      <inertia ixx="0.0" ixy="0.0" ixz="0.0" iyy="0.0" iyz="0.0" izz="0.0" />
      </inertial>
    </link>
  <link name="right_hand">
    <inertial>
      <mass value="0.45" />
      <origin xyz="0.015000 -0.153000 0.014000" rpy="0 0 0" />
      <inertia ixx="0.00558" ixy="0.00073" ixz="0.00034" iyy="0.00216" iyz="-0.0006" izz="0.0047" />
      </inertial>
    <visual>
      <origin xyz="0.000000 0.000000 0.000000" rpy="0.000000 -0.000000 0.000000" />
      <geometry>
        <mesh filename="meshes/hand_mesh.STL" scale="0.006100 0.006100 0.006100" />
        </geometry>
      <material name="body_color_R" />
      </visual>
    </link>
  <link name="right_upperleg_virtual">
    <inertial>
      <mass value="0.0" />
      <origin xyz="0.000000 0.000000 0.000000" rpy="0 0 0" />
      <inertia ixx="0.0" ixy="0.0" ixz="0.0" iyy="0.0" iyz="0.0" izz="0.0" />
      </inertial>
    </link>
  <link name="right_upperleg_virtual_2">
    <inertial>
      <mass value="0.0" />
      <origin xyz="0.000000 0.000000 0.000000" rpy="0 0 0" />
      <inertia ixx="0.0" ixy="0.0" ixz="0.0" iyy="0.0" iyz="0.0" izz="0.0" />
      </inertial>
    </link>
  <link name="right_upperleg">
    <inertial>
      <mass value="9.22" />
      <origin xyz="-0.018000 -0.188000 0.014000" rpy="0 0 0" />
      <inertia ixx="0.1497" ixy="0.00872" ixz="-0.00071" iyy="0.04005" iyz="-0.00872" izz="0.1602" />
      </inertial>
    <visual>
      <origin xyz="0.000000 -0.050000 0.000000" rpy="0.000000 -0.000000 0.000000" />
      <geometry>
        <mesh filename="meshes/upperleg_mesh.STL" scale="0.006200 0.006400 0.006900" />
        </geometry>
      <material name="body_color_R" />
      </visual>
    </link>
  <link name="right_lowerleg">
    <inertial>
      <mass value="3.6" />
      <origin xyz="-0.021000 -0.181000 0.003000" rpy="0 0 0" />
      <inertia ixx="0.05471" ixy="0.00112" ixz="0.00028" iyy="0.00698" iyz="0.00174" izz="0.05471" />
      </inertial>
    <visual>
      <origin xyz="0.000000 0.000000 0.000000" rpy="0.000000 -0.000000 0.000000" />
      <geometry>
        <mesh filename="meshes/lowerleg_mesh.STL" scale="0.006300 0.006600 0.007000" />
        </geometry>
      <material name="body_color_R" />
      </visual>
    <visual>
      <origin xyz="0.000000 0.000000 0.000000" rpy="0.000000 -0.000000 0.000000" />
      <geometry>
        <mesh filename="meshes/knee_mesh.STL" scale="0.005600 0.005600 0.005600" />
        </geometry>
      <material name="body_color_R" />
      </visual>
    </link>
  <link name="right_foot_virtual">
    <inertial>
      <mass value="0.0" />
      <origin xyz="0.000000 0.000000 0.000000" rpy="0 0 0" />
      <inertia ixx="0.0" ixy="0.0" ixz="0.0" iyy="0.0" iyz="0.0" izz="0.0" />
      </inertial>
    </link>
  <link name="right_foot">
    <inertial>
      <mass value="0.9" />
      <origin xyz="0.068000 -0.027000 0.005000" rpy="0 0 0" />
      <inertia ixx="0.00081" ixy="0.00048" ixz="-0.00018" iyy="0.00385" iyz="0.0" izz="0.00364" />
      </inertial>
    <visual>
      <origin xyz="0.000000 0.000000 0.000000" rpy="0.000000 -0.000000 0.000000" />
      <geometry>
        <mesh filename="meshes/foot_mesh.STL" scale="0.006700 0.006700 0.006700" />
        </geometry>
      <material name="body_color_R" />
      </visual>
    </link>
  <joint name="left_hip_Z" type="revolute">
    <parent link="middle_pelvis" />
    <child link="left_upperleg_virtual" />
    <origin xyz="0.010231 -0.101571 -0.098882" rpy="0.000000 -0.000000 0.000000" />
    <axis xyz="0.000000 0.000000 1.000000" />
    <limit effort="185.0" velocity="12.0" lower="-1.047196667" upper="3.14159" />
    </joint>
  <joint name="left_hip_X" type="revolute">
    <parent link="left_upperleg_virtual" />
    <child link="left_upperleg_virtual_2" />
    <origin xyz="0.000000 0.000000 0.000000" rpy="0.000000 -0.000000 0.000000" />
    <axis xyz="1.000000 0.000000 0.000000" />
    <limit effort="120.0" velocity="12.0" lower="-1.047196667" upper="1.570795" />
    </joint>
  <joint name="left_hip_Y" type="revolute">
    <parent link="left_upperleg_virtual_2" />
    <child link="left_upperleg" />
    <origin xyz="0.000000 0.000000 0.000000" rpy="0.000000 -0.000000 0.000000" />
    <axis xyz="0.000000 -1.000000 0.000000" />
    <limit effort="60.0" velocity="12.0" lower="-1.570795" upper="1.047196667" />
    </joint>
  <joint name="left_knee_Z" type="revolute">
    <parent link="left_upperleg" />
    <child link="left_lowerleg" />
    <origin xyz="0.000000 -0.434596 0.000000" rpy="0.000000 -0.000000 0.000000" />
    <axis xyz="0.000000 0.000000 -1.000000" />
    <limit effort="130.0" velocity="18.6" lower="0.0" upper="3.14159" />
    </joint>
  <joint name="left_ankle_Z" type="revolute">
    <parent link="left_lowerleg" />
    <child link="left_foot_virtual" />
    <origin xyz="0.000000 -0.421444 0.000000" rpy="0.000000 -0.000000 0.000000" />
    <axis xyz="0.000000 0.000000 1.000000" />
    <limit effort="126.0" velocity="12.7" lower="-1.570795" upper="0.7853975" />
    </joint>
  <joint name="left_ankle_X" type="revolute">
    <parent link="left_foot_virtual" />
    <child link="left_foot" />
    <origin xyz="0.000000 0.000000 0.000000" rpy="0.000000 -0.000000 0.000000" />
    <axis xyz="-1.000000 0.000000 0.000000" />
    <limit effort="20.0" velocity="2.0" lower="-0.523598333" upper="0.785398" />
    </joint>
  <joint name="middle_lumbar_Z" type="revolute">
    <parent link="middle_pelvis" />
    <child link="middle_abdomen_virtual" />
    <origin xyz="0.000000 0.000000 0.000000" rpy="0.000000 -0.000000 0.000000" />
    <axis xyz="0.000000 0.000000 -1.000000" />
    <limit effort="190.0" velocity="5.2" lower="-0.785398" upper="3.14159" />
    </joint>
  <joint name="middle_lumbar_X" type="revolute">
    <parent link="middle_abdomen_virtual" />
    <child link="middle_abdomen" />
    <origin xyz="0.000000 0.000000 0.000000" rpy="0.000000 -0.000000 0.000000" />
    <axis xyz="1.000000 0.000000 0.000000" />
    <limit effort="160.0" velocity="5.2" lower="-0.785398" upper="0.785398" />
    </joint>
  <joint name="middle_thoracic_Z" type="revolute">
    <parent link="middle_abdomen" />
    <child link="middle_thorax_virtual" />
    <origin xyz="0.000000 0.151020 0.000000" rpy="0.000000 -0.000000 0.000000" />
    <axis xyz="0.000000 0.000000 -1.000000" />
    <limit effort="190.0" velocity="5.2" lower="-0.392699" upper="1.0472" />
    </joint>
  <joint name="middle_thoracic_X" type="revolute">
    <parent link="middle_thorax_virtual" />
    <child link="middle_thorax_virtual_2" />
    <origin xyz="0.000000 0.000000 0.000000" rpy="0.000000 -0.000000 0.000000" />
    <axis xyz="1.000000 0.000000 0.000000" />
    <limit effort="190.0" velocity="5.2" lower="-1.0472" upper="1.0472" />
    </joint>
  <joint name="middle_thoracic_Y" type="revolute">
    <parent link="middle_thorax_virtual_2" />
    <child link="middle_thorax" />
    <origin xyz="0.000000 0.000000 0.000000" rpy="0.000000 -0.000000 0.000000" />
    <axis xyz="0.000000 1.000000 0.000000" />
    <limit effort="185.0" velocity="2.0" lower="-1.0472" upper="1.0472" />
    </joint>
  <joint name="left_clavicle_joint_X" type="revolute">
    <parent link="middle_thorax" />
    <child link="left_clavicle" />
    <origin xyz="0.000000 0.340255 0.000000" rpy="0.000000 -0.000000 0.000000" />
    <axis xyz="1.000000 0.000000 0.000000" />
    <limit effort="100.0" velocity="14.0" lower="-0.349066" upper="1.0472" />
    </joint>
  <joint name="left_shoulder_Z" type="revolute">
    <parent link="left_clavicle" />
    <child link="left_upperarm_virtual" />
    <origin xyz="-0.000186 -0.056848 -0.171085" rpy="0.000000 -0.000000 0.000000" />
    <axis xyz="0.000000 0.000000 1.000000" />
    <limit effort="92.0" velocity="17.6" lower="-3.14159" upper="3.14159" />
    </joint>
  <joint name="left_shoulder_X" type="revolute">
    <parent link="left_upperarm_virtual" />
    <child link="left_upperarm_virtual_2" />
    <origin xyz="0.000000 0.000000 0.000000" rpy="0.000000 -0.000000 0.000000" />
    <axis xyz="1.000000 0.000000 0.000000" />
    <limit effort="71.0" velocity="6.0" lower="-1.0472" upper="3.14159" />
    </joint>
  <joint name="left_shoulder_Y" type="revolute">
    <parent link="left_upperarm_virtual_2" />
    <child link="left_upperarm" />
    <origin xyz="0.000000 0.000000 0.000000" rpy="0.000000 -0.000000 0.000000" />
    <axis xyz="0.000000 -1.000000 0.000000" />
    <limit effort="52.0" velocity="6.0" lower="-1.5708" upper="3.14159" />
    </joint>
  <joint name="left_elbow_Z" type="revolute">
    <parent link="left_upperarm" />
    <child link="left_lowerarm_virtual" />
    <origin xyz="0.000000 -0.329023 0.000000" rpy="0.000000 -0.000000 0.000000" />
    <axis xyz="0.000000 0.000000 1.000000" />
    <limit effort="77.0" velocity="19.9" lower="0.0" upper="2.617991667" />
    </joint>
  <joint name="left_elbow_Y" type="revolute">
    <parent link="left_lowerarm_virtual" />
    <child link="left_lowerarm" />
    <origin xyz="0.000000 0.000000 0.000000" rpy="0.000000 -0.000000 0.000000" />
    <axis xyz="0.000000 -1.000000 0.000000" />
    <limit effort="15.0" velocity="6.0" lower="-0.349066" upper="3.14159" />
    </joint>
  <joint name="left_wrist_Z" type="revolute">
    <parent link="left_lowerarm" />
    <child link="left_hand_virtual" />
    <origin xyz="0.000000 -0.263739 0.000000" rpy="0.000000 -0.000000 0.000000" />
    <axis xyz="0.000000 0.000000 1.000000" />
    <limit effort="185.0" velocity="25.0" lower="-1.5708" upper="1.5708" />
    </joint>
  <joint name="left_wrist_X" type="revolute">
    <parent link="left_hand_virtual" />
    <child link="left_hand" />
    <origin xyz="0.000000 0.000000 0.000000" rpy="0.000000 -0.000000 0.000000" />
    <axis xyz="1.000000 0.000000 0.000000" />
    <limit effort="100.0" velocity="6.0" lower="-0.785398" upper="0.785398" />
    </joint>
  <joint name="middle_cervical_Z" type="revolute">
    <parent link="middle_thorax" />
    <child link="middle_head_virtual" />
    <origin xyz="0.000000 0.340255 0.000000" rpy="0.000000 -0.000000 0.000000" />
    <axis xyz="0.000000 0.000000 -1.000000" />
    <limit effort="100.0" velocity="8.7" lower="-1.5708" upper="1.5708" />
    </joint>
  <joint name="middle_cervical_X" type="revolute">
    <parent link="middle_head_virtual" />
    <child link="middle_head_virtual_2" />
    <origin xyz="0.000000 0.000000 0.000000" rpy="0.000000 -0.000000 0.000000" />
    <axis xyz="1.000000 0.000000 0.000000" />
    <limit effort="100.0" velocity="8.7" lower="-1.5708" upper="1.5708" />
    </joint>
  <joint name="middle_cervical_Y" type="revolute">
    <parent link="middle_head_virtual_2" />
    <child link="middle_head" />
    <origin xyz="0.000000 0.000000 0.000000" rpy="0.000000 -0.000000 0.000000" />
    <axis xyz="0.000000 1.000000 0.000000" />
    <limit effort="100.0" velocity="8.7" lower="-1.5708" upper="1.5708" />
    </joint>
  <joint name="right_clavicle_joint_X" type="revolute">
    <parent link="middle_thorax" />
    <child link="right_clavicle" />
    <origin xyz="0.000000 0.340255 0.000000" rpy="0.000000 -0.000000 0.000000" />
    <axis xyz="-1.000000 0.000000 0.000000" />
    <limit effort="100.0" velocity="14.0" lower="-0.349066" upper="1.0472" />
    </joint>
  <joint name="right_shoulder_Z" type="revolute">
    <parent link="right_clavicle" />
    <child link="right_upperarm_virtual" />
    <origin xyz="0.000186 -0.059493 0.171085" rpy="0.000000 -0.000000 0.000000" />
    <axis xyz="0.000000 0.000000 1.000000" />
    <limit effort="92.0" velocity="17.6" lower="-3.14159" upper="3.14159" />
    </joint>
  <joint name="right_shoulder_X" type="revolute">
    <parent link="right_upperarm_virtual" />
    <child link="right_upperarm_virtual_2" />
    <origin xyz="0.000000 0.000000 0.000000" rpy="0.000000 -0.000000 0.000000" />
    <axis xyz="-1.000000 0.000000 0.000000" />
    <limit effort="71.0" velocity="6.0" lower="-1.0472" upper="3.14159" />
    </joint>
  <joint name="right_shoulder_Y" type="revolute">
    <parent link="right_upperarm_virtual_2" />
    <child link="right_upperarm" />
    <origin xyz="0.000000 0.000000 0.000000" rpy="0.000000 -0.000000 0.000000" />
    <axis xyz="0.000000 1.000000 0.000000" />
    <limit effort="52.0" velocity="6.0" lower="-1.5708" upper="3.14159" />
    </joint>
  <joint name="right_elbow_Z" type="revolute">
    <parent link="right_upperarm" />
    <child link="right_lowerarm_virtual" />
    <origin xyz="0.000000 -0.336200 0.000000" rpy="0.000000 -0.000000 0.000000" />
    <axis xyz="0.000000 0.000000 1.000000" />
    <limit effort="77.0" velocity="19.9" lower="0.0" upper="2.617991667" />
    </joint>
  <joint name="right_elbow_Y" type="revolute">
    <parent link="right_lowerarm_virtual" />
    <child link="right_lowerarm" />
    <origin xyz="0.000000 0.000000 0.000000" rpy="0.000000 -0.000000 0.000000" />
    <axis xyz="0.000000 1.000000 0.000000" />
    <limit effort="15.0" velocity="6.0" lower="-0.349066" upper="3.14159" />
    </joint>
  <joint name="right_wrist_Z" type="revolute">
    <parent link="right_lowerarm" />
    <child link="right_hand_virtual" />
    <origin xyz="0.000000 -0.258125 0.000000" rpy="0.000000 -0.000000 0.000000" />
    <axis xyz="0.000000 0.000000 1.000000" />
    <limit effort="100.0" velocity="25.0" lower="-1.5708" upper="1.5708" />
    </joint>
  <joint name="right_wrist_X" type="revolute">
    <parent link="right_hand_virtual" />
    <child link="right_hand" />
    <origin xyz="0.000000 0.000000 0.000000" rpy="0.000000 -0.000000 0.000000" />
    <axis xyz="-1.000000 0.000000 0.000000" />
    <limit effort="100.0" velocity="6.0" lower="-0.785398" upper="0.785398" />
    </joint>
  <joint name="right_hip_Z" type="revolute">
    <parent link="middle_pelvis" />
    <child link="right_upperleg_virtual" />
    <origin xyz="0.010231 -0.101353 0.099106" rpy="0.000000 -0.000000 0.000000" />
    <axis xyz="0.000000 0.000000 1.000000" />
    <limit effort="185.0" velocity="12.0" lower="-1.047196667" upper="3.14159" />
    </joint>
  <joint name="right_hip_X" type="revolute">
    <parent link="right_upperleg_virtual" />
    <child link="right_upperleg_virtual_2" />
    <origin xyz="0.000000 0.000000 0.000000" rpy="0.000000 -0.000000 0.000000" />
    <axis xyz="-1.000000 0.000000 0.000000" />
    <limit effort="120.0" velocity="6.0" lower="-1.047196667" upper="1.570795" />
    </joint>
  <joint name="right_hip_Y" type="revolute">
    <parent link="right_upperleg_virtual_2" />
    <child link="right_upperleg" />
    <origin xyz="0.000000 0.000000 0.000000" rpy="0.000000 -0.000000 0.000000" />
    <axis xyz="0.000000 1.000000 0.000000" />
    <limit effort="60.0" velocity="6.0" lower="-1.570795" upper="1.047196667" />
    </joint>
  <joint name="right_knee_Z" type="revolute">
    <parent link="right_upperleg" />
    <child link="right_lowerleg" />
    <origin xyz="0.000000 -0.421699 0.000000" rpy="0.000000 -0.000000 0.000000" />
    <axis xyz="0.000000 0.000000 -1.000000" />
    <limit effort="130.0" velocity="18.6" lower="0.0" upper="3.14159" />
    </joint>
  <joint name="right_ankle_Z" type="revolute">
    <parent link="right_lowerleg" />
    <child link="right_foot_virtual" />
    <origin xyz="0.000000 -0.423210 0.000000" rpy="0.000000 -0.000000 0.000000" />
    <axis xyz="0.000000 0.000000 1.000000" />
    <limit effort="126.0" velocity="12.7" lower="-1.570795" upper="0.7853975" />
    </joint>
  <joint name="right_ankle_X" type="revolute">
    <parent link="right_foot_virtual" />
    <child link="right_foot" />
    <origin xyz="0.000000 0.000000 0.000000" rpy="0.000000 -0.000000 0.000000" />
    <axis xyz="1.000000 0.000000 0.000000" />
    <limit effort="20.0" velocity="6.0" lower="-0.523598333" upper="0.785398" />
    </joint>
  <link name="RPSI">
    <visual>
      <origin xyz="0 0 0" rpy="0 0 0" />
      <geometry>
        <sphere radius="0.02" />
        </geometry>
      <material name="marker_color" />
      </visual>
    </link>
  <joint name="joint_RPSI" type="fixed">
    <parent link="middle_pelvis" />
    <child link="RPSI" />
    <origin xyz="-0.091834 -0.000151 0.047034" rpy="0.000000 -0.000000 0.000000" />
    </joint>
  <link name="LPSI">
    <visual>
      <origin xyz="0 0 0" rpy="0 0 0" />
      <geometry>
        <sphere radius="0.02" />
        </geometry>
      <material name="marker_color" />
      </visual>
    </link>
  <joint name="joint_LPSI" type="fixed">
    <parent link="middle_pelvis" />
    <child link="LPSI" />
    <origin xyz="-0.093162 0.000151 -0.047034" rpy="0.000000 -0.000000 0.000000" />
    </joint>
  <link name="RASI">
    <visual>
      <origin xyz="0 0 0" rpy="0 0 0" />
      <geometry>
        <sphere radius="0.02" />
        </geometry>
      <material name="marker_color" />
      </visual>
    </link>
  <joint name="joint_RASI" type="fixed">
    <parent link="middle_pelvis" />
    <child link="RASI" />
    <origin xyz="0.089945 0.000151 0.137087" rpy="0.000000 -0.000000 0.000000" />
    </joint>
  <link name="LASI">
    <visual>
      <origin xyz="0 0 0" rpy="0 0 0" />
      <geometry>
        <sphere radius="0.02" />
        </geometry>
      <material name="marker_color" />
      </visual>
    </link>
  <joint name="joint_LASI" type="fixed">
    <parent link="middle_pelvis" />
    <child link="LASI" />
    <origin xyz="0.095051 -0.000151 -0.137087" rpy="0.000000 -0.000000 0.000000" />
    </joint>
  <link name="TV8">
    <visual>
      <origin xyz="0 0 0" rpy="0 0 0" />
      <geometry>
        <sphere radius="0.02" />
        </geometry>
      <material name="marker_color" />
      </visual>
    </link>
  <joint name="joint_TV8" type="fixed">
    <parent link="middle_thorax" />
    <child link="TV8" />
    <origin xyz="-0.161747 0.122107 -0.021745" rpy="0.000000 -0.000000 0.000000" />
    </joint>
  <link name="TV12">
    <visual>
      <origin xyz="0 0 0" rpy="0 0 0" />
      <geometry>
        <sphere radius="0.02" />
        </geometry>
      <material name="marker_color" />
      </visual>
    </link>
  <joint name="joint_TV12" type="fixed">
    <parent link="middle_thorax" />
    <child link="TV12" />
    <origin xyz="-0.120813 0.006848 -0.011001" rpy="0.000000 -0.000000 0.000000" />
    </joint>
  <link name="SJN">
    <visual>
      <origin xyz="0 0 0" rpy="0 0 0" />
      <geometry>
        <sphere radius="0.02" />
        </geometry>
      <material name="marker_color" />
      </visual>
    </link>
  <joint name="joint_SJN" type="fixed">
    <parent link="middle_thorax" />
    <child link="SJN" />
    <origin xyz="-0.007864 0.286131 -0.020909" rpy="0.000000 -0.000000 0.000000" />
    </joint>
  <link name="STRN">
    <visual>
      <origin xyz="0 0 0" rpy="0 0 0" />
      <geometry>
        <sphere radius="0.02" />
        </geometry>
      <material name="marker_color" />
      </visual>
    </link>
  <joint name="joint_STRN" type="fixed">
    <parent link="middle_thorax" />
    <child link="STRN" />
    <origin xyz="0.047803 0.134196 -0.017730" rpy="0.000000 -0.000000 0.000000" />
    </joint>
  <link name="RSHO">
    <visual>
      <origin xyz="0 0 0" rpy="0 0 0" />
      <geometry>
        <sphere radius="0.02" />
        </geometry>
      <material name="marker_color" />
      </visual>
    </link>
  <joint name="joint_RSHO" type="fixed">
    <parent link="middle_head" />
    <child link="RSHO" />
    <origin xyz="-0.014506 0.000987 0.170471" rpy="0.000000 -0.000000 0.000000" />
    </joint>
  <link name="LSHO">
    <visual>
      <origin xyz="0 0 0" rpy="0 0 0" />
      <geometry>
        <sphere radius="0.02" />
        </geometry>
      <material name="marker_color" />
      </visual>
    </link>
  <joint name="joint_LSHO" type="fixed">
    <parent link="middle_head" />
    <child link="LSHO" />
    <origin xyz="0.014506 -0.000987 -0.170471" rpy="0.000000 -0.000000 0.000000" />
    </joint>
  <link name="C7">
    <visual>
      <origin xyz="0 0 0" rpy="0 0 0" />
      <geometry>
        <sphere radius="0.02" />
        </geometry>
      <material name="marker_color" />
      </visual>
    </link>
  <joint name="joint_C7" type="fixed">
    <parent link="middle_head" />
    <child link="C7" />
    <origin xyz="-0.069122 0.028920 -0.006498" rpy="0.000000 -0.000000 0.000000" />
    </joint>
  <link name="BHD">
    <visual>
      <origin xyz="0 0 0" rpy="0 0 0" />
      <geometry>
        <sphere radius="0.02" />
        </geometry>
      <material name="marker_color" />
      </visual>
    </link>
  <joint name="joint_BHD" type="fixed">
    <parent link="middle_head" />
    <child link="BHD" />
    <origin xyz="-0.103129 0.131296 -0.012798" rpy="0.000000 -0.000000 0.000000" />
    </joint>
  <link name="RHD">
    <visual>
      <origin xyz="0 0 0" rpy="0 0 0" />
      <geometry>
        <sphere radius="0.02" />
        </geometry>
      <material name="marker_color" />
      </visual>
    </link>
  <joint name="joint_RHD" type="fixed">
    <parent link="middle_head" />
    <child link="RHD" />
    <origin xyz="0.011525 0.225249 0.103834" rpy="0.000000 -0.000000 0.000000" />
    </joint>
  <link name="LHD">
    <visual>
      <origin xyz="0 0 0" rpy="0 0 0" />
      <geometry>
        <sphere radius="0.02" />
        </geometry>
      <material name="marker_color" />
      </visual>
    </link>
  <joint name="joint_LHD" type="fixed">
    <parent link="middle_head" />
    <child link="LHD" />
    <origin xyz="0.011525 0.214348 -0.096751" rpy="0.000000 -0.000000 0.000000" />
    </joint>
  <link name="FHD">
    <visual>
      <origin xyz="0 0 0" rpy="0 0 0" />
      <geometry>
        <sphere radius="0.02" />
        </geometry>
      <material name="marker_color" />
      </visual>
    </link>
  <joint name="joint_FHD" type="fixed">
    <parent link="middle_head" />
    <child link="FHD" />
    <origin xyz="0.080078 0.282136 0.005715" rpy="0.000000 -0.000000 0.000000" />
    </joint>
  <link name="RMELB">
    <visual>
      <origin xyz="0 0 0" rpy="0 0 0" />
      <geometry>
        <sphere radius="0.02" />
        </geometry>
      <material name="marker_color" />
      </visual>
    </link>
  <joint name="joint_RMELB" type="fixed">
    <parent link="right_upperarm" />
    <child link="RMELB" />
    <origin xyz="0.000000 -0.324253 -0.043456" rpy="0.000000 -0.000000 0.000000" />
    </joint>
  <link name="RELB">
    <visual>
      <origin xyz="0 0 0" rpy="0 0 0" />
      <geometry>
        <sphere radius="0.02" />
        </geometry>
      <material name="marker_color" />
      </visual>
    </link>
  <joint name="joint_RELB" type="fixed">
    <parent link="right_upperarm" />
    <child link="RELB" />
    <origin xyz="0.000000 -0.348147 0.043456" rpy="0.000000 -0.000000 0.000000" />
    </joint>
  <link name="LMELB">
    <visual>
      <origin xyz="0 0 0" rpy="0 0 0" />
      <geometry>
        <sphere radius="0.02" />
        </geometry>
      <material name="marker_color" />
      </visual>
    </link>
  <joint name="joint_LMELB" type="fixed">
    <parent link="left_upperarm" />
    <child link="LMELB" />
    <origin xyz="-0.000000 -0.328884 0.039930" rpy="0.000000 -0.000000 0.000000" />
    </joint>
  <link name="LELB">
    <visual>
      <origin xyz="0 0 0" rpy="0 0 0" />
      <geometry>
        <sphere radius="0.02" />
        </geometry>
      <material name="marker_color" />
      </visual>
    </link>
  <joint name="joint_LELB" type="fixed">
    <parent link="left_upperarm" />
    <child link="LELB" />
    <origin xyz="0.000000 -0.329162 -0.039930" rpy="0.000000 -0.000000 0.000000" />
    </joint>
  <link name="RWRI">
    <visual>
      <origin xyz="0 0 0" rpy="0 0 0" />
      <geometry>
        <sphere radius="0.02" />
        </geometry>
      <material name="marker_color" />
      </visual>
    </link>
  <joint name="joint_RWRI" type="fixed">
    <parent link="right_lowerarm" />
    <child link="RWRI" />
    <origin xyz="0.000000 -0.269902 0.035407" rpy="0.000000 -0.000000 0.000000" />
    </joint>
  <link name="RMWRI">
    <visual>
      <origin xyz="0 0 0" rpy="0 0 0" />
      <geometry>
        <sphere radius="0.02" />
        </geometry>
      <material name="marker_color" />
      </visual>
    </link>
  <joint name="joint_RMWRI" type="fixed">
    <parent link="right_lowerarm" />
    <child link="RMWRI" />
    <origin xyz="0.000000 -0.246347 -0.035407" rpy="0.000000 -0.000000 0.000000" />
    </joint>
  <link name="LWRI">
    <visual>
      <origin xyz="0 0 0" rpy="0 0 0" />
      <geometry>
        <sphere radius="0.02" />
        </geometry>
      <material name="marker_color" />
      </visual>
    </link>
  <joint name="joint_LWRI" type="fixed">
    <parent link="left_lowerarm" />
    <child link="LWRI" />
    <origin xyz="0.000000 -0.262352 -0.038126" rpy="0.000000 -0.000000 0.000000" />
    </joint>
  <link name="LMWRI">
    <visual>
      <origin xyz="0 0 0" rpy="0 0 0" />
      <geometry>
        <sphere radius="0.02" />
        </geometry>
      <material name="marker_color" />
      </visual>
    </link>
  <joint name="joint_LMWRI" type="fixed">
    <parent link="left_lowerarm" />
    <child link="LMWRI" />
    <origin xyz="0.000000 -0.265126 0.038126" rpy="0.000000 -0.000000 0.000000" />
    </joint>
  <link name="RHM2">
    <visual>
      <origin xyz="0 0 0" rpy="0 0 0" />
      <geometry>
        <sphere radius="0.02" />
        </geometry>
      <material name="marker_color" />
      </visual>
    </link>
  <joint name="joint_RHM2" type="fixed">
    <parent link="right_hand" />
    <child link="RHM2" />
    <origin xyz="0.009171 -0.099861 0.003500" rpy="0.000000 -0.000000 0.000000" />
    </joint>
  <link name="RHM5">
    <visual>
      <origin xyz="0 0 0" rpy="0 0 0" />
      <geometry>
        <sphere radius="0.02" />
        </geometry>
      <material name="marker_color" />
      </visual>
    </link>
  <joint name="joint_RHM5" type="fixed">
    <parent link="right_hand" />
    <child link="RHM5" />
    <origin xyz="0.018481 -0.062389 -0.054753" rpy="0.000000 -0.000000 0.000000" />
    </joint>
  <link name="LHM2">
    <visual>
      <origin xyz="0 0 0" rpy="0 0 0" />
      <geometry>
        <sphere radius="0.02" />
        </geometry>
      <material name="marker_color" />
      </visual>
    </link>
  <joint name="joint_LHM2" type="fixed">
    <parent link="left_hand" />
    <child link="LHM2" />
    <origin xyz="0.007909 -0.090039 -0.011203" rpy="0.000000 -0.000000 0.000000" />
    </joint>
  <link name="LHM5">
    <visual>
      <origin xyz="0 0 0" rpy="0 0 0" />
      <geometry>
        <sphere radius="0.02" />
        </geometry>
      <material name="marker_color" />
      </visual>
    </link>
  <joint name="joint_LHM5" type="fixed">
    <parent link="left_hand" />
    <child link="LHM5" />
    <origin xyz="0.027030 -0.066475 0.048335" rpy="0.000000 -0.000000 0.000000" />
    </joint>
  <link name="RKNE">
    <visual>
      <origin xyz="0 0 0" rpy="0 0 0" />
      <geometry>
        <sphere radius="0.02" />
        </geometry>
      <material name="marker_color" />
      </visual>
    </link>
  <joint name="joint_RKNE" type="fixed">
    <parent link="right_upperleg" />
    <child link="RKNE" />
    <origin xyz="0.000000 -0.417261 0.061732" rpy="0.000000 -0.000000 0.000000" />
    </joint>
  <link name="RMKNE">
    <visual>
      <origin xyz="0 0 0" rpy="0 0 0" />
      <geometry>
        <sphere radius="0.02" />
        </geometry>
      <material name="marker_color" />
      </visual>
    </link>
  <joint name="joint_RMKNE" type="fixed">
    <parent link="right_upperleg" />
    <child link="RMKNE" />
    <origin xyz="-0.000000 -0.426138 -0.061732" rpy="0.000000 -0.000000 0.000000" />
    </joint>
  <link name="RTHI1">
    <visual>
      <origin xyz="0 0 0" rpy="0 0 0" />
      <geometry>
        <sphere radius="0.02" />
        </geometry>
      <material name="marker_color" />
      </visual>
    </link>
  <joint name="joint_RTHI1" type="fixed">
    <parent link="right_upperleg" />
    <child link="RTHI1" />
    <origin xyz="0.029180 -0.171643 0.096178" rpy="0.000000 -0.000000 0.000000" />
    </joint>
  <link name="LKNE">
    <visual>
      <origin xyz="0 0 0" rpy="0 0 0" />
      <geometry>
        <sphere radius="0.02" />
        </geometry>
      <material name="marker_color" />
      </visual>
    </link>
  <joint name="joint_LKNE" type="fixed">
    <parent link="left_upperleg" />
    <child link="LKNE" />
    <origin xyz="0.000000 -0.429230 -0.058361" rpy="0.000000 -0.000000 0.000000" />
    </joint>
  <link name="LMKNE">
    <visual>
      <origin xyz="0 0 0" rpy="0 0 0" />
      <geometry>
        <sphere radius="0.02" />
        </geometry>
      <material name="marker_color" />
      </visual>
    </link>
  <joint name="joint_LMKNE" type="fixed">
    <parent link="left_upperleg" />
    <child link="LMKNE" />
    <origin xyz="0.000000 -0.439962 0.058361" rpy="0.000000 -0.000000 0.000000" />
    </joint>
  <link name="LTHI1">
    <visual>
      <origin xyz="0 0 0" rpy="0 0 0" />
      <geometry>
        <sphere radius="0.02" />
        </geometry>
      <material name="marker_color" />
      </visual>
    </link>
  <joint name="joint_LTHI1" type="fixed">
    <parent link="left_upperleg" />
    <child link="LTHI1" />
    <origin xyz="0.008536 -0.315189 -0.074300" rpy="0.000000 -0.000000 0.000000" />
    </joint>
  <link name="RANK">
    <visual>
      <origin xyz="0 0 0" rpy="0 0 0" />
      <geometry>
        <sphere radius="0.02" />
        </geometry>
      <material name="marker_color" />
      </visual>
    </link>
  <joint name="joint_RANK" type="fixed">
    <parent link="right_lowerleg" />
    <child link="RANK" />
    <origin xyz="-0.032995 -0.437742 0.033411" rpy="0.000000 -0.000000 0.000000" />
    </joint>
  <link name="RMANK">
    <visual>
      <origin xyz="0 0 0" rpy="0 0 0" />
      <geometry>
        <sphere radius="0.02" />
        </geometry>
      <material name="marker_color" />
      </visual>
    </link>
  <joint name="joint_RMANK" type="fixed">
    <parent link="right_lowerleg" />
    <child link="RMANK" />
    <origin xyz="0.032995 -0.408677 -0.033411" rpy="0.000000 -0.000000 0.000000" />
    </joint>
  <link name="RTIB1">
    <visual>
      <origin xyz="0 0 0" rpy="0 0 0" />
      <geometry>
        <sphere radius="0.02" />
        </geometry>
      <material name="marker_color" />
      </visual>
    </link>
  <joint name="joint_RTIB1" type="fixed">
    <parent link="right_lowerleg" />
    <child link="RTIB1" />
    <origin xyz="-0.013130 -0.132641 0.073223" rpy="0.000000 -0.000000 0.000000" />
    </joint>
  <link name="LANK">
    <visual>
      <origin xyz="0 0 0" rpy="0 0 0" />
      <geometry>
        <sphere radius="0.02" />
        </geometry>
      <material name="marker_color" />
      </visual>
    </link>
  <joint name="joint_LANK" type="fixed">
    <parent link="left_lowerleg" />
    <child link="LANK" />
    <origin xyz="-0.024692 -0.435968 -0.038288" rpy="0.000000 -0.000000 0.000000" />
    </joint>
  <link name="LMANK">
    <visual>
      <origin xyz="0 0 0" rpy="0 0 0" />
      <geometry>
        <sphere radius="0.02" />
        </geometry>
      <material name="marker_color" />
      </visual>
    </link>
  <joint name="joint_LMANK" type="fixed">
    <parent link="left_lowerleg" />
    <child link="LMANK" />
    <origin xyz="0.024692 -0.406920 0.038288" rpy="0.000000 -0.000000 0.000000" />
    </joint>
  <link name="LTIB1">
    <visual>
      <origin xyz="0 0 0" rpy="0 0 0" />
      <geometry>
        <sphere radius="0.02" />
        </geometry>
      <material name="marker_color" />
      </visual>
    </link>
  <joint name="joint_LTIB1" type="fixed">
    <parent link="left_lowerleg" />
    <child link="LTIB1" />
    <origin xyz="-0.029607 -0.271167 -0.059874" rpy="0.000000 -0.000000 0.000000" />
    </joint>
  <link name="RHEE">
    <visual>
      <origin xyz="0 0 0" rpy="0 0 0" />
      <geometry>
        <sphere radius="0.02" />
        </geometry>
      <material name="marker_color" />
      </visual>
    </link>
  <joint name="joint_RHEE" type="fixed">
    <parent link="right_foot" />
    <child link="RHEE" />
    <origin xyz="-0.065686 -0.045199 0.026241" rpy="0.000000 -0.000000 0.000000" />
    </joint>
  <link name="R5MHD">
    <visual>
      <origin xyz="0 0 0" rpy="0 0 0" />
      <geometry>
        <sphere radius="0.02" />
        </geometry>
      <material name="marker_color" />
      </visual>
    </link>
  <joint name="joint_R5MHD" type="fixed">
    <parent link="right_foot" />
    <child link="R5MHD" />
    <origin xyz="0.102926 -0.042258 0.071490" rpy="0.000000 -0.000000 0.000000" />
    </joint>
  <link name="RTOE">
    <visual>
      <origin xyz="0 0 0" rpy="0 0 0" />
      <geometry>
        <sphere radius="0.02" />
        </geometry>
      <material name="marker_color" />
      </visual>
    </link>
  <joint name="joint_RTOE" type="fixed">
    <parent link="right_foot" />
    <child link="RTOE" />
    <origin xyz="0.145294 -0.048140 -0.019008" rpy="0.000000 -0.000000 0.000000" />
    </joint>
  <link name="LHEE">
    <visual>
      <origin xyz="0 0 0" rpy="0 0 0" />
      <geometry>
        <sphere radius="0.02" />
        </geometry>
      <material name="marker_color" />
      </visual>
    </link>
  <joint name="joint_LHEE" type="fixed">
    <parent link="left_foot" />
    <child link="LHEE" />
    <origin xyz="-0.064193 -0.049369 -0.026376" rpy="0.000000 -0.000000 0.000000" />
    </joint>
  <link name="L5MHD">
    <visual>
      <origin xyz="0 0 0" rpy="0 0 0" />
      <geometry>
        <sphere radius="0.02" />
        </geometry>
      <material name="marker_color" />
      </visual>
    </link>
  <joint name="joint_L5MHD" type="fixed">
    <parent link="left_foot" />
    <child link="L5MHD" />
    <origin xyz="0.112506 -0.050723 -0.068307" rpy="0.000000 -0.000000 0.000000" />
    </joint>
  <link name="LTOE">
    <visual>
      <origin xyz="0 0 0" rpy="0 0 0" />
      <geometry>
        <sphere radius="0.02" />
        </geometry>
      <material name="marker_color" />
      </visual>
    </link>
  <joint name="joint_LTOE" type="fixed">
    <parent link="left_foot" />
    <child link="LTOE" />
    <origin xyz="0.156353 -0.048016 0.015555" rpy="0.000000 -0.000000 0.000000" />
    </joint>
  </robot>
